{"name": "test_function", "status": "failed", "statusDetails": {"message": "AssertionError: 不相等\nassert 1 == 2\n  +1\n  -2", "trace": "def test_function():\n>       assert 1 == 2, '不相等'\nE       AssertionError: 不相等\nE       assert 1 == 2\nE         +1\nE         -2\n\nPython_Pytest\\com\\kxj\\case\\test_03_exception.py:11: AssertionError"}, "start": 1617330625648, "stop": 1617330625648, "uuid": "18e6d1fa-a2ed-4749-b23b-5f67fffcf2db", "historyId": "884999172d9f99848924cfcc56c6e759", "testCaseId": "c7d31f057ab664b6578663d9d3781563", "fullName": "com.kxj.case.test_03_exception#test_function", "labels": [{"name": "parentSuite", "value": "com.kxj.case"}, {"name": "suite", "value": "test_03_exception"}, {"name": "host", "value": "DESKTOP-4IJL66C"}, {"name": "thread", "value": "3396-MainThread"}, {"name": "framework", "value": "pytest"}, {"name": "language", "value": "cpython3"}, {"name": "package", "value": "com.kxj.case.test_03_exception"}]}